Workbook
Name canjes: Tabla6[]
Name COMPILADO: Resumen!$B$3:$C$12
Name DatosExternos_1: PONDERADAS!#REF!
Name lastreview: #REF!
Name lastreview1: #REF!
Name lastreview2: #REF!
Name Nemotecnicos: Emisiones[Mnemotécnico SEN]
Name RNG_Actions: #REF!
Name RNG_AGENT: #REF!
Name RNG_ARROWS: #REF!
Name RNG_CHART1: #REF!
Name RNG_CHART2: #REF!
Name RNG_CHART3: #REF!
Name RNG_CHART4: #REF!
Name RNG_CHART5: #REF!
Name RNG_CHART6: #REF!
Name RNG_CHART7: #REF!
Name RNG_CHART8: #REF!
Name RNG_CLASS_CE_ABS: #REF!
Name RNG_CURRENT_DATE: #REF!
Name RNG_DEAL_HEADER: #REF!
Name RNG_GO_BACK: #REF!
Name RNG_HYP: #REF!
Name RNG_Industry: #REF!
Name RNG_INFORMATION: #REF!
Name RNG_LAST_DATE: #REF!
Name RNG_Markers: #REF!
Name RNG_PERFORM_SUM_ABS: #REF!
Name RNG_PERFORM_SUM_PERCENT: #REF!
Name RNG_PERFORMANCE_ABS: #REF!
Name RNG_PERFORMANCE_Number: #REF!
Name RNG_PERFORMANCE_SUMMARY: #REF!
Name RNG_PREPAYMENT: #REF!
Name RNG_PREVIOUS_DATE: #REF!
Name RNG_ROW_DOWN: #REF!
Name RNG_RTNG: #REF!
Name RNG_Scale: #REF!
Name Transaction_Data_Int: #REF!
Name Type: '[2]All Actions 1 Mar - 15 May'!#REF!
Name VALOR_OP: Resumen!$C$3

Sheet Resumen
B3: Operación | C3: 657
B4: Fecha | C4: =_xlfn.XLOOKUP(C3,'Canjes desagregado'!B:B,'Canjes desagregado'!C:C,0) -> 46003
B5: Monto Canjeado (MC) | C5: {=+_xlfn.XLOOKUP($C$4&$C$3,HISTORICO!D:D&HISTORICO!$B:$B,HISTORICO!H:H,"",0,1)} -> 213678300000
B6: Valor de giro | C6: {=+_xlfn.XLOOKUP($C$4&$C$3,HISTORICO!D:D&HISTORICO!$B:$B,HISTORICO!I:I,"",0,1)} -> 75740
B7: Efecto cupones | C7: {=+_xlfn.XLOOKUP($C$4&$C$3,HISTORICO!D:D&HISTORICO!$B:$B,HISTORICO!J:J,"",0,1)} -> 0
B8: Indexaciones | C8: {=+_xlfn.XLOOKUP($C$4&$C$3,HISTORICO!D:D&HISTORICO!$B:$B,HISTORICO!L:L,"",0,1)} -> 0
B9: Saldo de la deuda | C9: {=+_xlfn.XLOOKUP($C$4&$C$3,HISTORICO!D:D&HISTORICO!$B:$B,HISTORICO!N:N,"",0,1)} -> -7678300000
B10: Costo Fiscal Neto | C10: {=+_xlfn.XLOOKUP($C$4&$C$3,HISTORICO!D:D&HISTORICO!$B:$B,HISTORICO!U:U,"",0,1)} -> -7678224260
B11: Efecto Fiscal Neto (EFN) | C11: {=+_xlfn.XLOOKUP($C$4&$C$3,HISTORICO!D:D&HISTORICO!$B:$B,HISTORICO!X:X,"",0,1)} -> -0.035933571
B12: Costo de Oportunidad | C12: =+_xlfn.XLOOKUP(C4,COSTO_OPORTUNIDAD!C:C,COSTO_OPORTUNIDAD!EA:EA) -> 0.12279
B13: E.F.N - C.O | C13: =C12-C11 -> 0.15872357
B16: Indicador | C16: Valor | E16: =B16 -> Indicador | F16: =C16 -> Valor
B17: Monto Canjeado (Valor nominal recibido) | C17: =-SUMIFS('Canjes desagregado'!S:S, 'Canjes desagregado'!B:B, C3, 'Canjes desagregado'!E:E, "Títulos Recogidos por la Nación") -> 213678300000 | E17: =B17 -> Monto Canjeado (Valor nominal recibido) | F17: =C17 -> 213678300000
B18: Valor nominal entregado | C18: =SUMIFS('Canjes desagregado'!S:S, 'Canjes desagregado'!B:B, C3, 'Canjes desagregado'!E:E, "Títulos Entregados por la Nación") -> 206000000000 | E18: =B18 -> Valor nominal entregado | F18: =C18 -> 206000000000
B19: Diferencia nominal (reducción de deuda) | C19: =C18-C17 -> -7678300000 | E19: =B19 -> Diferencia nominal (reducción de deuda) | F19: =C19 -> -7678300000
B20: Costo total entregado | C20: =SUMIFS('Canjes desagregado'!U:U, 'Canjes desagregado'!B:B, C3, 'Canjes desagregado'!E:E, "*Entregados*") -> 204661000000 | E20: =B20 -> Costo total entregado | F20: =C20 -> 204661000000
B21: Diferencia en costo | C21: =SUMIFS('Canjes desagregado'!U:U, 'Canjes desagregado'!B:B, C3, 'Canjes desagregado'!E:E, "Títulos Recogidos por la Nación")+C20 -> -75740 | E21: =B21 -> Diferencia en costo | F21: =C21 -> -75740
B22: Precio promedio recibido (coste/nominal) | C22: =AVERAGEIF(pond[Concepto],"*Recogidos*",pond[Precio Sucio]) -> 95.78 | E22: =B22 -> Precio promedio recibido (coste/nominal) | F22: =C22 -> 95.78
B23: Precio promedio entregado (coste/nominal) | C23: =AVERAGEIF(pond[Concepto],"*Entregados*",pond[Precio Sucio]) -> 99.35 | E23: =B23 -> Precio promedio entregado (coste/nominal) | F23: =C23 -> 99.35
B24: Tasa de cupón ponderada (Recibidos) | C24: =SUMPRODUCT(PONDERADAS!D2:D2,PONDERADAS!K2:K2)/100 -> 0 | E24: =B24 -> Tasa de cupón ponderada (Recibidos) | F24: =IFERROR(C24,"-") -> 0
B25: Tasa de cupón ponderada (Entregados) | C25: =SUMPRODUCT(PONDERADAS!D3:D3,PONDERADAS!K3:K3)/100 -> 0.11 | E25: =B25 -> Tasa de cupón ponderada (Entregados) | F25: =C25 -> 0.11
B26: Rendimiento promedio ponderado recibido | C26: =SUMPRODUCT(PONDERADAS!E2:E2,PONDERADAS!K2:K2)/100 -> 0.09581
B27: Rendimiento promedio ponderado entregado | C27: =SUMPRODUCT(PONDERADAS!E3:E3,PONDERADAS!K3:K3)/100 -> 0.12375
B28: Madurez promedio ponderada recibida (años) | C28: =SUMPRODUCT(PONDERADAS!I2:I2,PONDERADAS!K2:K2) -> 0.47123288
B29: Madurez promedio ponderada entregada (años) | C29: =SUMPRODUCT(PONDERADAS!I3:I3,PONDERADAS!K3:K3) -> 3.6958904
B30: Impacto en la vida media VPP en años | C30: =VPP!O3 -> #REF!

Sheet PONDERADAS
A1: Operación | B1: Concepto | C1: Fecha Vto | D1: Cupon | E1: Tasa de Corte (%) | F1: Precio Sucio | G1: Precio Limpio | H1: Nominal COP | I1: Madurez | J1: Costo COP | K1: % DE PESO | L1: nom_abs | M1: cost_abs2 | N1: AÑO
A2: 657 | B2: Títulos Recogidos por la Nación | C2: 46175 | D2: 0 | E2: 9.581 | F2: 95.78 | G2: 95.680154 | H2: -213678300000 | I2: 0.47123288 | J2: -204661075740 | K2: =IF(pond[[#This Row],[Concepto]] = "Títulos Recogidos por la Nación", pond[[#This Row],[Nominal COP]] / SUMIF(pond[Concepto], "Títulos Recogidos por la Nación", pond[Nominal COP]), IF(pond[[#This Row],[Concepto]] = "Títulos Entregados por la Nación", pond[[#This Row],[Nominal COP]] / SUMIF(pond[Concepto], "Títulos Entregados por la Nación", pond[Nominal COP]), 0)) -> 1 | L2: =ABS(pond[[#This Row],[Nominal COP]]) -> 213678300000 | M2: =ABS(pond[[#This Row],[Costo COP]]) -> 204661075740 | N2: =YEAR(pond[[#This Row],[Fecha Vto]]) -> 2026
A3: 657 | B3: Títulos Entregados por la Nación | C3: 47352 | D3: 11 | E3: 12.375 | F3: 99.35 | G3: 95.97495 | H3: 206000000000 | I3: 3.6958904 | J3: 204661000000 | K3: =IF(pond[[#This Row],[Concepto]] = "Títulos Recogidos por la Nación", pond[[#This Row],[Nominal COP]] / SUMIF(pond[Concepto], "Títulos Recogidos por la Nación", pond[Nominal COP]), IF(pond[[#This Row],[Concepto]] = "Títulos Entregados por la Nación", pond[[#This Row],[Nominal COP]] / SUMIF(pond[Concepto], "Títulos Entregados por la Nación", pond[Nominal COP]), 0)) -> 1 | L3: =ABS(pond[[#This Row],[Nominal COP]]) -> 206000000000 | M3: =ABS(pond[[#This Row],[Costo COP]]) -> 204661000000 | N3: =YEAR(pond[[#This Row],[Fecha Vto]]) -> 2029
A4: Total | L4: =SUBTOTAL(109,pond[nom_abs]) -> 419678300000 | M4: =SUBTOTAL(109,pond[cost_abs2]) -> 409322075740

Sheet VPP
A1: ='[3]Resumen Interna'!H13 -> Perfil de vencimientos | B1: ='[3]Resumen Interna'!J14 -> Total interna GNC | H1: VPP - Antes de OMD | K1: VPP - DESPUES de OMD | N1: IMPACTO
A2: ='[3]Resumen Interna'!H14 -> Periodo | B2: ='[3]Resumen Interna'!I14 -> TES | C2: TES-OMD | D2: TOTAL | E2: TOTAL - OMD | F2: ='[3]Resumen Interna'!K14 -> % | H2: VPP TES Principal | I2: {=SUMPRODUCT(($A$3:$A$40-$A$3),$B$3:$B$40)/SUM($B$3:$B$40)} -> 10.619587 | K2: VPP TES Principal | L2: {=SUMPRODUCT(($A$3:$A$40-$A$3),$C$3:$C$40)/SUM($C$3:$C$40)} -> 10.623101 | N2: VPP TES Principal | O2: =L2-I2 -> 0.0035137761
A3: ='[3]Resumen Interna'!H15 -> 2025 | B3: ='[3]Resumen Interna'!I15 -> 13006267 | C3: =B3-PONDERADAS!L2/1000000 -> 12792589 | D3: ='[3]Resumen Interna'!J15 -> 1.2084702e+08 | E3: =D3-PONDERADAS!L2/1000000 -> 1.2063334e+08 | F3: ='[3]Resumen Interna'!K15 -> 0.16961535 | H3: VPP Total | I3: {=SUMPRODUCT(($A$3:$A$40-$A$3),$D$3:$D$40)/SUM($D$3:$D$40)} -> 8.9936927 | K3: VPP Total | L3: {=SUMPRODUCT(($A$3:$A$40-$A$3),$E$3:$E$40)/SUM($E$3:$E$40)} -> #REF! | N3: VPP Total | O3: =L3-I3 -> #REF!
A4: ='[3]Resumen Interna'!H16 -> 2026 | B4: ='[3]Resumen Interna'!I16 -> 40258143 | C4: =B4 -> 40258143 | D4: ='[3]Resumen Interna'!J16 -> 49668966 | E4: =D4-PONDERADAS!#REF!/1000000 -> #REF! | F4: ='[3]Resumen Interna'!K16 -> 0.069713092
A5: ='[3]Resumen Interna'!H17 -> 2027 | B5: ='[3]Resumen Interna'!I17 -> 46505339 | C5: =B5 -> 46505339 | D5: ='[3]Resumen Interna'!J17 -> 46506006 | E5: =D5 -> 46506006 | F5: ='[3]Resumen Interna'!K17 -> 0.065273706
A6: ='[3]Resumen Interna'!H18 -> 2028 | B6: ='[3]Resumen Interna'!I18 -> 40127204 | C6: =B6 -> 40127204 | D6: ='[3]Resumen Interna'!J18 -> 40507588 | E6: =D6 -> 40507588 | F6: ='[3]Resumen Interna'!K18 -> 0.0568546
A7: ='[3]Resumen Interna'!H19 -> 2029 | B7: ='[3]Resumen Interna'!I19 -> 42412431 | C7: =B7 -> 42412431 | D7: ='[3]Resumen Interna'!J19 -> 42412431 | E7: =D7+PONDERADAS!L3/1000000 -> 42618431 | F7: ='[3]Resumen Interna'!K19 -> 0.05952815
A8: ='[3]Resumen Interna'!H20 -> 2030 | B8: ='[3]Resumen Interna'!I20 -> 27749357 | C8: =B8 -> 27749357 | D8: ='[3]Resumen Interna'!J20 -> 27749358 | E8: =D8 -> 27749358 | F8: ='[3]Resumen Interna'!K20 -> 0.038947731
A9: ='[3]Resumen Interna'!H21 -> 2031 | B9: ='[3]Resumen Interna'!I21 -> 35351314 | C9: =B9 -> 35351314 | D9: ='[3]Resumen Interna'!J21 -> 35351320 | E9: =D9 -> 35351320 | F9: ='[3]Resumen Interna'!K21 -> 0.049617498
A10: ='[3]Resumen Interna'!H22 -> 2032 | B10: ='[3]Resumen Interna'!I22 -> 27992627 | C10: =B10 -> 27992627 | D10: ='[3]Resumen Interna'!J22 -> 29468261 | E10: =D10 -> 29468261 | F10: ='[3]Resumen Interna'!K22 -> 0.041360305
A11: ='[3]Resumen Interna'!H23 -> 2033 | B11: ='[3]Resumen Interna'!I23 -> 47461545 | C11: =B11 -> 47461545 | D11: ='[3]Resumen Interna'!J23 -> 47461545 | E11: =D11 -> 47461545 | F11: ='[3]Resumen Interna'!K23 -> 0.066614856
A12: ='[3]Resumen Interna'!H24 -> 2034 | B12: ='[3]Resumen Interna'!I24 -> 28484312 | C12: =B12 -> 28484312 | D12: ='[3]Resumen Interna'!J24 -> 28484312 | E12: =D12 -> 28484312 | F12: ='[3]Resumen Interna'!K24 -> 0.039979279
A13: ='[3]Resumen Interna'!H25 -> 2035 | B13: ='[3]Resumen Interna'!I25 -> 37750683 | C13: =B13 -> 37750683 | D13: ='[3]Resumen Interna'!J25 -> 37750683 | E13: =D13 -> 37750683 | F13: ='[3]Resumen Interna'!K25 -> 0.052985134
A14: ='[3]Resumen Interna'!H26 -> 2036 | B14: ='[3]Resumen Interna'!I26 -> 28868529 | C14: =B14 -> 28868529 | D14: ='[3]Resumen Interna'!J26 -> 28868529 | E14: =D14 -> 28868529 | F14: ='[3]Resumen Interna'!K26 -> 0.040518548
A15: ='[3]Resumen Interna'!H27 -> 2037 | B15: ='[3]Resumen Interna'!I27 -> 43566794 | C15: =B15 -> 43566794 | D15: ='[3]Resumen Interna'!J27 -> 43566794 | E15: =D15 -> 43566794 | F15: ='[3]Resumen Interna'!K27 -> 0.061148361
A16: ='[3]Resumen Interna'!H28 -> 2038 | B16: ='[3]Resumen Interna'!I28 -> 0 | C16: =B16 -> 0 | D16: ='[3]Resumen Interna'!J28 -> 0 | E16: =D16 -> 0 | F16: ='[3]Resumen Interna'!K28 -> 0
A17: ='[3]Resumen Interna'!H29 -> 2039 | B17: ='[3]Resumen Interna'!I29 -> 0 | C17: =B17 -> 0 | D17: ='[3]Resumen Interna'!J29 -> 0 | E17: =D17 -> 0 | F17: ='[3]Resumen Interna'!K29 -> 0
A18: ='[3]Resumen Interna'!H30 -> 2040 | B18: ='[3]Resumen Interna'!I30 -> 2728167.3 | C18: =B18 -> 2728167.3 | D18: ='[3]Resumen Interna'!J30 -> 2728167.3 | E18: =D18 -> 2728167.3 | F18: ='[3]Resumen Interna'!K30 -> 0.003829131
A19: ='[3]Resumen Interna'!H31 -> 2041 | B19: ='[3]Resumen Interna'!I31 -> 4998438.8 | C19: =B19 -> 4998438.8 | D19: ='[3]Resumen Interna'!J31 -> 4998438.8 | E19: =D19 -> 4998438.8 | F19: ='[3]Resumen Interna'!K31 -> 0.0070155803
... A38: ='[3]Resumen Interna'!H50 -> 2060 | B38: ='[3]Resumen Interna'!I50 -> 0 | C38: =B38 -> 0 | D38: ='[3]Resumen Interna'!J50 -> 0 | E38: =D38 -> 0 | F38: ='[3]Resumen Interna'!K50 -> 0
A39: 2061 | B39: ='[3]Resumen Interna'!I51 -> 0 | C39: =B39 -> 0 | D39: ='[3]Resumen Interna'!J51 -> 0 | E39: =D39 -> 0 | F39: ='[3]Resumen Interna'!K51 -> 0
A40: 2062 | B40: ='[3]Resumen Interna'!I52 -> 0 | C40: =B40 -> 0 | D40: ='[3]Resumen Interna'!J52 -> 0 | E40: =D40 -> 0 | F40: ='[3]Resumen Interna'!K52 -> 0

Sheet Emisiones
B2: Titulo | C2: Plazo | D2: Tipo Plazo | E2: Moneda | F2: Emisión | G2: Mnemotécnico SEN | H2: Fecha Inicio Vigencia | I2: Fecha Vencim. | J2: Tasa de Interés | K2: Tasa Spread | L2: Signo | M2: Periodo Interés | N2: Tipo | O2: Código ISIN | P2: Código CFI | Q2: Saldo en Circulación | R2: Base de Ponderación | S2: Conteo de Plazo | T2: Modo de Pago
B3: 21 | C3: 16 | E3: COP | F3: 53059 | G3: TFIT16240724 | H3: 39653 | I3: 45497 | J3: 10 | K3: 0 | M3: A | N3: FIJA | O3: COL17CT02385 | P3: DMFTFR | R3: 365 | S3: Comercial | T3: Vencido
B4: 21 | C4: 8 | E4: COP | F4: 56219 | G4: TFIT08261125 | H4: 43065 | I4: 45987 | J4: 6.25 | K4: 0 | M4: A | N4: FIJA | O4: COL17CT03557 | P4: DMFTFR | R4: 365 | S4: Comercial | T4: Vencido
B5: 21 | C5: 15 | E5: COP | F5: 54542 | G5: TFIT15260826 | H5: 40781 | I5: 46260 | J5: 7.5 | K5: 0 | M5: A | N5: FIJA | O5: COL17CT02625 | P5: DMFTFR | R5: 365 | S5: Comercial | T5: Vencido
B6: 21 | C6: 8 | E6: COP | F6: 56552 | G6: TFIT08031127 | H6: 43772 | I6: 46694 | J6: 5.75 | K6: 0 | M6: A | N6: FIJA | O6: COL17CT03672 | P6: DBFTFR | R6: 365 | S6: Comercial | T6: Vencido
B7: 21 | C7: 16 | E7: COP | F7: 55029 | G7: TFIT16280428 | H7: 41027 | I7: 46871 | J7: 6 | K7: 0 | M7: A | N7: FIJA | O7: COL17CT02914 | P7: DMFTFR | R7: 365 | S7: Comercial | T7: Vencido
B8: 21 | C8: 5 | E8: COP | G8: TFIT05220829 | H8: 45526 | I8: 47352 | J8: 11 | K8: 0 | M8: A | N8: FIJA | O8: COL17CT03995 | P8: DMFTFR | R8: 365 | S8: Comercial | T8: Vencido
B9: 21 | C9: 16 | E9: COP | F9: 55684 | G9: TFIT16180930 | H9: 41900 | I9: 47744 | J9: 7.75 | K9: 0 | M9: A | N9: FIJA | O9: COL17CT03342 | P9: DMFTFR | R9: 365 | S9: Comercial | T9: Vencido
B10: 21 | C10: 10 | E10: COP | F10: 57165 | G10: TFIT10260331 | H10: 44281 | I10: 47933 | J10: 7 | K10: 0 | M10: A | N10: FIJA | O10: COL17CT03771 | P10: DBFTFR | R10: 365 | S10: Comercial | T10: Vencido
B11: 21 | C11: 10 | E11: COP | F11: 57278 | G11: TFVT10260331 | H11: 44281 | I11: 47933 | J11: 7 | K11: 0 | M11: A | N11: FIJA | O11: COL17CT03797 | P11: DBFTFR | R11: 365 | S11: Comercial | T11: Vencido
B12: 21 | C12: 16 | E12: COP | F12: 56059 | G12: TFIT16300632 | H12: 42551 | I12: 48395 | J12: 7 | K12: 0 | M12: A | N12: FIJA | O12: COL17CT03490 | P12: DMFTFR | R12: 365 | S12: Comercial | T12: Vencido
B13: 21 | C13: 11 | E13: COP | F13: 57836 | G13: TFIT11090233 | H13: 44601 | I13: 48619 | J13: 13.25 | K13: 0 | M13: A | N13: FIJA | O13: COL17CT03862 | P13: DBFTFR | R13: 365 | S13: Comercial | T13: Vencido
B14: 21 | C14: 16 | E14: COP | F14: 56377 | G14: TFIT16181034 | H14: 43391 | I14: 49235 | J14: 7.25 | K14: 0 | M14: A | N14: FIJA | O14: COL17CT03615 | P14: DBFTFR | R14: 365 | S14: Comercial | T14: Vencido
B15: 21 | C15: 16 | E15: COP | F15: 56970 | G15: TFIT16090736 | H15: 44021 | I15: 49865 | J15: 6.25 | K15: 0 | M15: A | N15: FIJA | O15: COL17CT03748 | P15: DBFTFR | R15: 365 | S15: Comercial | T15: Vencido
B16: 21 | C16: 16 | E16: COP | G16: TFIT16281140 | H16: 45624 | I16: 51468 | J16: 12.75 | K16: 0 | M16: A | N16: FIJA | O16: COL17CT04001 | P16: DBFTFR | R16: 365 | S16: Comercial | T16: Vencido
B17: 21 | C17: 21 | E17: COP | F17: 57407 | G17: TFIT21280542 | H17: 44344 | I17: 52014 | J17: 9.25 | K17: 0 | M17: A | N17: FIJA | O17: COL17CT03813 | P17: DBFTFR | R17: 365 | S17: Comercial | T17: Vencido
B18: 21 | C18: 23 | E18: COP | G18: TFIT23250746 | H18: 45132 | I18: 53533 | J18: 11.5 | K18: 0 | M18: A | N18: FIJA | O18: COL17CT03938 | R18: 365 | S18: Comercial | T18: Vencido
B19: 21 | C19: 31 | E19: COP | F19: 56840 | G19: TFIT31261050 | H19: 43764 | I19: 55087 | J19: 7.25 | K19: 0 | M19: A | N19: FIJA | O19: COL17CT03722 | P19: DBFTFR | R19: 365 | S19: Comercial | T19: Vencido
B20: 21 | C20: 17 | E20: UVR | F20: 49936 | G20: TUVT17230223 | H20: 38771 | I20: 44980 | J20: 4.75 | K20: 0 | M20: A | N20: FIJA | O20: COL17CT02088 | P20: DMFTFR | R20: 365 | S20: Comercial | T20: Vencido
B21: 21 | C21: 11 | E21: UVR | F21: 55738 | G21: TUVT11070525 | H21: 41766 | I21: 45784 | J21: 3.5 | K21: 0 | M21: A | N21: FIJA | O21: COL17CT03359 | P21: DMFTFR | R21: 365 | S21: Comercial | T21: Vencido
B22: 21 | C22: 11 | E22: UVR | F22: 56091 | G22: TUVT11170327 | H22: 42446 | I22: 46463 | J22: 3.3 | K22: 0 | M22: A | N22: FIJA | O22: COL17CT03508 | P22: DMFTFR | R22: 365 | S22: Comercial | T22: Vencido
B23: 21 | C23: 10 | E23: UVR | F23: 56614 | G23: TUVT10180429 | H23: 43573 | I23: 47226 | J23: 2.25 | K23: 0 | M23: A | N23: FIJA | O23: COL17CT03680 | P23: DBFTFR | R23: 365 | S23: Comercial | T23: Vencido
B24: 21 | C24: 6 | E24: UVR | G24: TUVT07220131 | H24: 47870 | I24: 47870 | J24: 6.5 | K24: 0 | M24: A | N24: FIJA
B25: 21 | C25: 20 | E25: UVR | F25: 55197 | G25: TUVT20250333 | H25: 41358 | I25: 48663 | J25: 3 | K25: 0 | M25: A | N25: FIJA | O25: COL17CT02963 | P25: DMFTFR | R25: 365 | S25: Comercial | T25: Vencido
B26: 21 | C26: 20 | E26: UVR | F26: 55930 | G26: TUVT20040435 | H26: 42098 | I26: 49403 | J26: 4.75 | K26: 0 | M26: A | N26: FIJA | O26: COL17CT03441 | P26: DMFTFR | R26: 365 | S26: Comercial | T26: Vencido
B27: 21 | C27: 18 | E27: UVR | F27: 56414 | G27: TUVT18250237 | H27: 43521 | I27: 50096 | J27: 3.75 | K27: 0 | M27: A | N27: FIJA | O27: COL17CT03623 | P27: DBFTFR | R27: 365 | S27: Comercial | T27: Vencido
B28: 21 | C28: 18 | E28: UVR | G28: TUVT17200341 | H28: 45371 | I28: 51580 | J28: 5 | K28: 0 | M28: A | N28: FIJA | O28: COL17CT03961 | P28: DBFTFR | R28: 365 | S28: Comercial | T28: Vencido
B29: 21 | C29: 32 | E29: UVR | F29: 56246 | G29: TUVT32160649 | H29: 42902 | I29: 54590 | J29: 3.75 | K29: 0 | M29: A | N29: FIJA | O29: COL17CT03565 | P29: DBFTFR | R29: 365 | S29: Comercial | T29: Vencido
B30: 21 | C30: 31 | E30: UVR | G30: TUVT31190555 | H30: 45431 | I30: 56753 | J30: 5.25 | K30: 0 | M30: A | N30: FIJA | O30: COL17CT03979 | P30: DBFTFR | R30: 365 | S30: Comercial | T30: Vencido
B31: 21 | C31: 37 | E31: UVR | G31: TUVT38010262 | I31: 59203 | J31: 6.5 | K31: 0 | M31: A | N31: FIJA | O31: FALTA
E32: COP | G32: COL17CT04084 | I32: 49313 | J32: 11.75 | K32: 0 | M32: A | N32: FIJA | O32: COL17CT04084
E33: COP | G33: COL17CT03987 | I33: 46084 | J33: 0 | K33: 0 | M33: A | N33: FIJA | O33: COL17CT03987
E34: COP | G34: COL17CT04027 | I34: 46175 | J34: 0 | K34: 0 | O34: COL17CT04027
E35: COP | G35: COL17CT03953 | I35: 46236 | J35: 0 | K35: 0

Sheet Canjes desagregado
A1: Año | B1: Operación | C1: Fecha Cumplimiento y/ liquidacion | D1: Canje | E1: Concepto | F1: Nemotécnico | G1: Denom | H1: Plazo | I1: Fecha Emision | J1: Fecha Vto | K1: Cupon | L1: Tasa de Corte (%) | M1: Precio Sucio | N1: Precio Limpio | O1: Intereses acumulados | P1: Intereses por devengar | Q1: Valor Nominal | R1: Valor Costo | S1: Nominal COP | T1: Verificador fecha y nemotécnico | U1: Costo COP | V1: UVR | W1: Efectos cupón | X1: Efecto Cupón (Signo) | Y1: Costo Fiscal | Z1: Saldo de la deuda | AA1: Inflación | AB1: UVR (Fin de periodo) | AC1: Delta_UVR | AD1: Indexaciones | AE1: % de cupón x devengar | AF1: Nuevo efecto cupón | AG1: Madurez | AH1: Operación2 | AI1: UVR (Fin de periodo)2 | AJ1: Indexaciones2 | AL1: Maduración | AM1: Maduración signo | AN1: Próximo cupón | AO1: % de cupón x devengar a 31 de diciembre | AP1: % de cupón x devengar a vencimiento del próximo año | AQ1: Cupón en año en curso | AR1: Cupón en siguiente año | AT1: Cupón en año en curso | AU1: Cupón en siguiente año
A2: =IF(C2="","",YEAR(C2)) -> 2025 | B2: 603 | C2: 45700 | D2: Tesorería | E2: Títulos Recogidos por la Nación | F2: TFIT15260826 | G2: =+_xlfn.XLOOKUP(F2,Emisiones[Mnemotécnico SEN],Emisiones[Moneda],"",0,1) -> COP | J2: =+_xlfn.XLOOKUP(F2,Emisiones[Mnemotécnico SEN],Emisiones[Fecha Vencim.],"",0,1) -> 46260 | K2: =+_xlfn.XLOOKUP(F2,Emisiones[Mnemotécnico SEN],Emisiones[Tasa de Interés],"",0,1) -> 7.5 | L2: 8.755 | M2: 101.683 | N2: =IF(C2="","",PRICE(C2,J2,K2%,L2%,100,1,3)) -> 98.189862 | O2: =IF(C2="","",M2-N2) -> 3.4931382 | P2: =IF(C2="","",100*K2%-O2) -> 4.0068618 | Q2: =IF(C2="","",IF(G2="UVR",S2/V2,S2)) -> -85000000000 | R2: =IF(C2="","",IF('Canjes desagregado'!$G2="UVR",'Canjes desagregado'!$V2*Q2*M2%,Q2*M2%)) -> -8.643055e+10 | S2: -85000000000 | T2: =IFERROR(IF(RIGHT(F2,2)=RIGHT(YEAR(J2),2),1,0),"") -> 1 | U2: =+IF(R2="","",R2) -> -8.643055e+10 | V2: =+IF(F2<>"",(_xlfn.XLOOKUP(C2,UVR[Fecha (dd/mm/aaaa)],UVR[Pesos colombianos por UVR],"",0,1)),"") -> 378.8353 | W2: =IF(C2="","",IF(CONCATENATE(DAY(C2),"/",MONTH(C2),"/",2000)-CONCATENATE(DAY(J2),"/",MONTH(J2),"/",2000)<0,K2%*ABS(S2),0)) -> 6375000000 | X2: =IF(S2<0,-W2,W2) -> -6375000000 | AB2: =IF(C2="","",ROUND(V2*(1+'Inflación observada '!$B$390%)^(("31-12-2025"-C2)/365),3)) -> 396.228 | AD2: =IF(C2="","",IF(G2="UVR",Q2*AB2-S2,0)) -> 0 | AE2: =IF(C2="","",P2/+(O2+P2)) -> 0.53424825 | AF2: =IF(C2="","",AE2*Q2*K2%) -> -3.4058326e+09 | AG2: =(Tabla6[[#This Row],[Fecha Vto]]-TODAY())/365 -> 0.70410959 | AJ2: =IF(C2="","",IF(G2="UVR",Q2*AI2-S2,0)) -> 0
A3: =IF(C3="","",YEAR(C3)) -> 2025 | B3: 603 | C3: 45700 | D3: Tesorería | E3: Títulos Entregados por la Nación | F3: TFIT23250746 | G3: =+_xlfn.XLOOKUP(F3,Emisiones[Mnemotécnico SEN],Emisiones[Moneda],"",0,1) -> COP | J3: =+_xlfn.XLOOKUP(F3,Emisiones[Mnemotécnico SEN],Emisiones[Fecha Vencim.],"",0,1) -> 53533 | K3: =+_xlfn.XLOOKUP(F3,Emisiones[Mnemotécnico SEN],Emisiones[Tasa de Interés],"",0,1) -> 11.5 | L3: 12.549 | M3: 98.499 | N3: =IF(C3="","",PRICE(C3,J3,K3%,L3%,100,1,3)) -> 92.134778 | O3: =IF(C3="","",M3-N3) -> 6.3642218 | P3: =IF(C3="","",100*K3%-O3) -> 5.1357782 | Q3: =IF(C3="","",IF(G3="UVR",S3/V3,S3)) -> 85000000000 | R3: =IF(C3="","",IF('Canjes desagregado'!$G3="UVR",'Canjes desagregado'!$V3*Q3*M3%,Q3*M3%)) -> 83724150000 | S3: 85000000000 | T3: =IFERROR(IF(RIGHT(F3,2)=RIGHT(YEAR(J3),2),1,0),"") -> 1 | U3: =+IF(R3="","",R3) -> 83724150000 | V3: =+IF(F3<>"",(_xlfn.XLOOKUP(C3,UVR[Fecha (dd/mm/aaaa)],UVR[Pesos colombianos por UVR],"",0,1)),"") -> 378.8353 | W3: =IF(C3="","",IF(CONCATENATE(DAY(C3),"/",MONTH(C3),"/",2000)-CONCATENATE(DAY(J3),"/",MONTH(J3),"/",2000)<0,K3%*ABS(S3),0)) -> 9775000000 | X3: =IF(S3<0,-W3,W3) -> 9775000000 | AB3: =IF(C3="","",ROUND(V3*(1+'Inflación observada '!$B$390%)^(("31-12-2025"-C3)/365),3)) -> 396.228 | AD3: =IF(C3="","",IF(G3="UVR",Q3*AB3-S3,0)) -> 0 | AE3: =IF(C3="","",P3/+(O3+P3)) -> 0.44658941 | AF3: =IF(C3="","",AE3*Q3*K3%) -> 4.3654114e+09 | AG3: =(Tabla6[[#This Row],[Fecha Vto]]-TODAY())/365 -> 20.630137 | AJ3: =IF(C3="","",IF(G3="UVR",Q3*AI3-S3,0)) -> 0
A4: =IF(C4="","",YEAR(C4)) -> 2025 | B4: 604 | C4: 45701 | D4: Tesorería | E4: Títulos Recogidos por la Nación | F4: TFIT15260826 | G4: =+_xlfn.XLOOKUP(F4,Emisiones[Mnemotécnico SEN],Emisiones[Moneda],"",0,1) -> COP | J4: =+_xlfn.XLOOKUP(F4,Emisiones[Mnemotécnico SEN],Emisiones[Fecha Vencim.],"",0,1) -> 46260 | K4: =+_xlfn.XLOOKUP(F4,Emisiones[Mnemotécnico SEN],Emisiones[Tasa de Interés],"",0,1) -> 7.5 | L4: 8.701 | M4: 101.78 | N4: =IF(C4="","",PRICE(C4,J4,K4%,L4%,100,1,3)) -> 98.266523 | O4: =IF(C4="","",M4-N4) -> 3.5134768 | P4: =IF(C4="","",100*K4%-O4) -> 3.9865232 | Q4: =IF(C4="","",IF(G4="UVR",S4/V4,S4)) -> -435000000000 | R4: =IF(C4="","",IF('Canjes desagregado'!$G4="UVR",'Canjes desagregado'!$V4*Q4*M4%,Q4*M4%)) -> -442743000000 | S4: -435000000000 | T4: =IFERROR(IF(RIGHT(F4,2)=RIGHT(YEAR(J4),2),1,0),"") -> 1 | U4: =+IF(R4="","",R4) -> -442743000000 | V4: =+IF(F4<>"",(_xlfn.XLOOKUP(C4,UVR[Fecha (dd/mm/aaaa)],UVR[Pesos colombianos por UVR],"",0,1)),"") -> 378.8914 | W4: =IF(C4="","",IF(CONCATENATE(DAY(C4),"/",MONTH(C4),"/",2000)-CONCATENATE(DAY(J4),"/",MONTH(J4),"/",2000)<0,K4%*ABS(S4),0)) -> 32625000000 | X4: =IF(S4<0,-W4,W4) -> -32625000000 | AB4: =IF(C4="","",ROUND(V4*(1+'Inflación observada '!$B$390%)^(("31-12-2025"-C4)/365),3)) -> 396.232 | AD4: =IF(C4="","",IF(G4="UVR",Q4*AB4-S4,0)) -> 0 | AE4: =IF(C4="","",P4/+(O4+P4)) -> 0.53153642 | AF4: =IF(C4="","",AE4*Q4*K4%) -> -1.7341376e+10 | AG4: =(Tabla6[[#This Row],[Fecha Vto]]-TODAY())/365 -> 0.70410959 | AJ4: =IF(C4="","",IF(G4="UVR",Q4*AI4-S4,0)) -> 0
A5: =IF(C5="","",YEAR(C5)) -> 2025 | B5: 604 | C5: 45701 | D5: Tesorería | E5: Títulos Entregados por la Nación | F5: TFIT16180930 | G5: =+_xlfn.XLOOKUP(F5,Emisiones[Mnemotécnico SEN],Emisiones[Moneda],"",0,1) -> COP | J5: =+_xlfn.XLOOKUP(F5,Emisiones[Mnemotécnico SEN],Emisiones[Fecha Vencim.],"",0,1) -> 47744 | K5: =+_xlfn.XLOOKUP(F5,Emisiones[Mnemotécnico SEN],Emisiones[Tasa de Interés],"",0,1) -> 7.75 | L5: 10.872 | M5: 90.451 | N5: =IF(C5="","",PRICE(C5,J5,K5%,L5%,100,1,3)) -> 87.308013 | O5: =IF(C5="","",M5-N5) -> 3.1429867 | P5: =IF(C5="","",100*K5%-O5) -> 4.6070133 | Q5: =IF(C5="","",IF(G5="UVR",S5/V5,S5)) -> 65000000000 | R5: =IF(C5="","",IF('Canjes desagregado'!$G5="UVR",'Canjes desagregado'!$V5*Q5*M5%,Q5*M5%)) -> 5.879315e+10 | S5: 65000000000 | T5: =IFERROR(IF(RIGHT(F5,2)=RIGHT(YEAR(J5),2),1,0),"") -> 1 | U5: =+IF(R5="","",R5) -> 5.879315e+10 | V5: =+IF(F5<>"",(_xlfn.XLOOKUP(C5,UVR[Fecha (dd/mm/aaaa)],UVR[Pesos colombianos por UVR],"",0,1)),"") -> 378.8914 | W5: =IF(C5="","",IF(CONCATENATE(DAY(C5),"/",MONTH(C5),"/",2000)-CONCATENATE(DAY(J5),"/",MONTH(J5),"/",2000)<0,K5%*ABS(S5),0)) -> 5037500000 | X5: =IF(S5<0,-W5,W5) -> 5037500000 | AB5: =IF(C5="","",ROUND(V5*(1+'Inflación observada '!$B$390%)^(("31-12-2025"-C5)/365),3)) -> 396.232 | AD5: =IF(C5="","",IF(G5="UVR",Q5*AB5-S5,0)) -> 0 | AE5: =IF(C5="","",P5/+(O5+P5)) -> 0.59445332 | AF5: =IF(C5="","",AE5*Q5*K5%) -> 2.9945586e+09 | AG5: =(Tabla6[[#This Row],[Fecha Vto]]-TODAY())/365 -> 4.769863 | AJ5: =IF(C5="","",IF(G5="UVR",Q5*AI5-S5,0)) -> 0
A6: =IF(C6="","",YEAR(C6)) -> 2025 | B6: 604 | C6: 45701 | D6: Tesorería | E6: Títulos Entregados por la Nación | F6: TFIT23250746 | G6: =+_xlfn.XLOOKUP(F6,Emisiones[Mnemotécnico SEN],Emisiones[Moneda],"",0,1) -> COP | J6: =+_xlfn.XLOOKUP(F6,Emisiones[Mnemotécnico SEN],Emisiones[Fecha Vencim.],"",0,1) -> 53533 | K6: =+_xlfn.XLOOKUP(F6,Emisiones[Mnemotécnico SEN],Emisiones[Tasa de Interés],"",0,1) -> 11.5 | L6: 12.569 | M6: 98.394 | N6: =IF(C6="","",PRICE(C6,J6,K6%,L6%,100,1,3)) -> 91.998099 | O6: =IF(C6="","",M6-N6) -> 6.3959006 | P6: =IF(C6="","",100*K6%-O6) -> 5.1040994 | Q6: =IF(C6="","",IF(G6="UVR",S6/V6,S6)) -> 370000000000 | R6: =IF(C6="","",IF('Canjes desagregado'!$G6="UVR",'Canjes desagregado'!$V6*Q6*M6%,Q6*M6%)) -> 364057800000 | S6: 370000000000 | T6: =IFERROR(IF(RIGHT(F6,2)=RIGHT(YEAR(J6),2),1,0),"") -> 1 | U6: =+IF(R6="","",R6) -> 364057800000 | V6: =+IF(F6<>"",(_xlfn.XLOOKUP(C6,UVR[Fecha (dd/mm/aaaa)],UVR[Pesos colombianos por UVR],"",0,1)),"") -> 378.8914 | W6: =IF(C6="","",IF(CONCATENATE(DAY(C6),"/",MONTH(C6),"/",2000)-CONCATENATE(DAY(J6),"/",MONTH(J6),"/",2000)<0,K6%*ABS(S6),0)) -> 42550000000 | X6: =IF(S6<0,-W6,W6) -> 42550000000 | AB6: =IF(C6="","",ROUND(V6*(1+'Inflación observada '!$B$390%)^(("31-12-2025"-C6)/365),3)) -> 396.232 | AD6: =IF(C6="","",IF(G6="UVR",Q6*AB6-S6,0)) -> 0 | AE6: =IF(C6="","",P6/+(O6+P6)) -> 0.44383473 | AF6: =IF(C6="","",AE6*Q6*K6%) -> 1.8885168e+10 | AG6: =(Tabla6[[#This Row],[Fecha Vto]]-TODAY())/365 -> 20.630137 | AJ6: =IF(C6="","",IF(G6="UVR",Q6*AI6-S6,0)) -> 0
A7: =IF(C7="","",YEAR(C7)) -> 2025 | B7: 605 | C7: 45702 | D7: Tesorería | E7: Títulos Recogidos por la Nación | F7: TFIT15260826 | G7: =+_xlfn.XLOOKUP(F7,Emisiones[Mnemotécnico SEN],Emisiones[Moneda],"",0,1) -> COP | J7: =+_xlfn.XLOOKUP(F7,Emisiones[Mnemotécnico SEN],Emisiones[Fecha Vencim.],"",0,1) -> 46260 | K7: =+_xlfn.XLOOKUP(F7,Emisiones[Mnemotécnico SEN],Emisiones[Tasa de Interés],"",0,1) -> 7.5 | L7: 8.751 | M7: 101.735 | N7: =IF(C7="","",PRICE(C7,J7,K7%,L7%,100,1,3)) -> 98.200995 | O7: =IF(C7="","",M7-N7) -> 3.5340052 | P7: =IF(C7="","",100*K7%-O7) -> 3.9659948 | Q7: =IF(C7="","",IF(G7="UVR",S7/V7,S7)) -> -85000000000 | R7: =IF(C7="","",IF('Canjes desagregado'!$G7="UVR",'Canjes desagregado'!$V7*Q7*M7%,Q7*M7%)) -> -86474750000 | S7: -85000000000 | T7: =IFERROR(IF(RIGHT(F7,2)=RIGHT(YEAR(J7),2),1,0),"") -> 1 | U7: =+IF(R7="","",R7) -> -86474750000 | V7: =+IF(F7<>"",(_xlfn.XLOOKUP(C7,UVR[Fecha (dd/mm/aaaa)],UVR[Pesos colombianos por UVR],"",0,1)),"") -> 378.9475 | W7: =IF(C7="","",IF(CONCATENATE(DAY(C7),"/",MONTH(C7),"/",2000)-CONCATENATE(DAY(J7),"/",MONTH(J7),"/",2000)<0,K7%*ABS(S7),0)) -> 6375000000 | X7: =IF(S7<0,-W7,W7) -> -6375000000 | AB7: =IF(C7="","",ROUND(V7*(1+'Inflación observada '!$B$390%)^(("31-12-2025"-C7)/365),3)) -> 396.235 | AD7: =IF(C7="","",IF(G7="UVR",Q7*AB7-S7,0)) -> 0 | AE7: =IF(C7="","",P7/+(O7+P7)) -> 0.5287993 | AF7: =IF(C7="","",AE7*Q7*K7%) -> -3.3710955e+09 | AG7: =(Tabla6[[#This Row],[Fecha Vto]]-TODAY())/365 -> 0.70410959 | AJ7: =IF(C7="","",IF(G7="UVR",Q7*AI7-S7,0)) -> 0
A8: =IF(C8="","",YEAR(C8)) -> 2025 | B8: 605 | C8: 45702 | D8: Tesorería | E8: Títulos Entregados por la Nación | F8: TFIT16180930 | G8: =+_xlfn.XLOOKUP(F8,Emisiones[Mnemotécnico SEN],Emisiones[Moneda],"",0,1) -> COP | J8: =+_xlfn.XLOOKUP(F8,Emisiones[Mnemotécnico SEN],Emisiones[Fecha Vencim.],"",0,1) -> 47744 | K8: =+_xlfn.XLOOKUP(F8,Emisiones[Mnemotécnico SEN],Emisiones[Tasa de Interés],"",0,1) -> 7.75 | L8: 10.784 | M8: 90.802 | N8: =IF(C8="","",PRICE(C8,J8,K8%,L8%,100,1,3)) -> 87.638458 | O8: =IF(C8="","",M8-N8) -> 3.1635423 | P8: =IF(C8="","",100*K8%-O8) -> 4.5864577 | Q8: =IF(C8="","",IF(G8="UVR",S8/V8,S8)) -> 15000000000 | R8: =IF(C8="","",IF('Canjes desagregado'!$G8="UVR",'Canjes desagregado'!$V8*Q8*M8%,Q8*M8%)) -> 13620300000 | S8: 15000000000 | T8: =IFERROR(IF(RIGHT(F8,2)=RIGHT(YEAR(J8),2),1,0),"") -> 1 | U8: =+IF(R8="","",R8) -> 13620300000 | V8: =+IF(F8<>"",(_xlfn.XLOOKUP(C8,UVR[Fecha (dd/mm/aaaa)],UVR[Pesos colombianos por UVR],"",0,1)),"") -> 378.9475 | W8: =IF(C8="","",IF(CONCATENATE(DAY(C8),"/",MONTH(C8),"/",2000)-CONCATENATE(DAY(J8),"/",MONTH(J8),"/",2000)<0,K8%*ABS(S8),0)) -> 1162500000 | X8: =IF(S8<0,-W8,W8) -> 1162500000 | AB8: =IF(C8="","",ROUND(V8*(1+'Inflación observada '!$B$390%)^(("31-12-2025"-C8)/365),3)) -> 396.235 | AD8: =IF(C8="","",IF(G8="UVR",Q8*AB8-S8,0)) -> 0 | AE8: =IF(C8="","",P8/+(O8+P8)) -> 0.59180099 | AF8: =IF(C8="","",AE8*Q8*K8%) -> 6.8796865e+08 | AG8: =(Tabla6[[#This Row],[Fecha Vto]]-TODAY())/365 -> 4.769863 | AJ8: =IF(C8="","",IF(G8="UVR",Q8*AI8-S8,0)) -> 0
A9: =IF(C9="","",YEAR(C9)) -> 2025 | B9: 605 | C9: 45702 | D9: Tesorería | E9: Títulos Entregados por la Nación | F9: TFIT23250746 | G9: =+_xlfn.XLOOKUP(F9,Emisiones[Mnemotécnico SEN],Emisiones[Moneda],"",0,1) -> COP | J9: =+_xlfn.XLOOKUP(F9,Emisiones[Mnemotécnico SEN],Emisiones[Fecha Vencim.],"",0,1) -> 53533 | K9: =+_xlfn.XLOOKUP(F9,Emisiones[Mnemotécnico SEN],Emisiones[Tasa de Interés],"",0,1) -> 11.5 | L9: 12.52 | M9: 98.763 | N9: =IF(C9="","",PRICE(C9,J9,K9%,L9%,100,1,3)) -> 92.334973 | O9: =IF(C9="","",M9-N9) -> 6.4280265 | P9: =IF(C9="","",100*K9%-O9) -> 5.0719735 | Q9: =IF(C9="","",IF(G9="UVR",S9/V9,S9)) -> 70000000000 | R9: =IF(C9="","",IF('Canjes desagregado'!$G9="UVR",'Canjes desagregado'!$V9*Q9*M9%,Q9*M9%)) -> 69134100000 | S9: 70000000000 | T9: =IFERROR(IF(RIGHT(F9,2)=RIGHT(YEAR(J9),2),1,0),"") -> 1 | U9: =+IF(R9="","",R9) -> 69134100000 | V9: =+IF(F9<>"",(_xlfn.XLOOKUP(C9,UVR[Fecha (dd/mm/aaaa)],UVR[Pesos colombianos por UVR],"",0,1)),"") -> 378.9475 | W9: =IF(C9="","",IF(CONCATENATE(DAY(C9),"/",MONTH(C9),"/",2000)-CONCATENATE(DAY(J9),"/",MONTH(J9),"/",2000)<0,K9%*ABS(S9),0)) -> 8050000000 | X9: =IF(S9<0,-W9,W9) -> 8050000000 | AB9: =IF(C9="","",ROUND(V9*(1+'Inflación observada '!$B$390%)^(("31-12-2025"-C9)/365),3)) -> 396.235 | AD9: =IF(C9="","",IF(G9="UVR",Q9*AB9-S9,0)) -> 0 | AE9: =IF(C9="","",P9/+(O9+P9)) -> 0.44104117 | AF9: =IF(C9="","",AE9*Q9*K9%) -> 3.5503814e+09 | AG9: =(Tabla6[[#This Row],[Fecha Vto]]-TODAY())/365 -> 20.630137 | AJ9: =IF(C9="","",IF(G9="UVR",Q9*AI9-S9,0)) -> 0
A10: =IF(C10="","",YEAR(C10)) -> 2025 | B10: 606 | C10: 45706 | D10: Tesorería | E10: Títulos Recogidos por la Nación | F10: TFIT15260826 | G10: =+_xlfn.XLOOKUP(F10,Emisiones[Mnemotécnico SEN],Emisiones[Moneda],"",0,1) -> COP | J10: =+_xlfn.XLOOKUP(F10,Emisiones[Mnemotécnico SEN],Emisiones[Fecha Vencim.],"",0,1) -> 46260 | K10: =+_xlfn.XLOOKUP(F10,Emisiones[Mnemotécnico SEN],Emisiones[Tasa de Interés],"",0,1) -> 7.5 | L10: 8.8 | M10: 101.762 | N10: =IF(C10="","",PRICE(C10,J10,K10%,L10%,100,1,3)) -> 98.146011 | O10: =IF(C10="","",M10-N10) -> 3.6159895 | P10: =IF(C10="","",100*K10%-O10) -> 3.8840105 | Q10: =IF(C10="","",IF(G10="UVR",S10/V10,S10)) -> -594000000000 | R10: =IF(C10="","",IF('Canjes desagregado'!$G10="UVR",'Canjes desagregado'!$V10*Q10*M10%,Q10*M10%)) -> -604466280000 | S10: -594000000000 | T10: =IFERROR(IF(RIGHT(F10,2)=RIGHT(YEAR(J10),2),1,0),"") -> 1 | U10: =+IF(R10="","",R10) -> -604466280000 | V10: =+IF(F10<>"",(_xlfn.XLOOKUP(C10,UVR[Fecha (dd/mm/aaaa)],UVR[Pesos colombianos por UVR],"",0,1)),"") -> 379.3837 | W10: =IF(C10="","",IF(CONCATENATE(DAY(C10),"/",MONTH(C10),"/",2000)-CONCATENATE(DAY(J10),"/",MONTH(J10),"/",2000)<0,K10%*ABS(S10),0)) -> 44550000000 | X10: =IF(S10<0,-W10,W10) -> -44550000000 | AB10: =IF(C10="","",ROUND(V10*(1+'Inflación observada '!$B$390%)^(("31-12-2025"-C10)/365),3)) -> 396.47 | AD10: =IF(C10="","",IF(G10="UVR",Q10*AB10-S10,0)) -> 0 | AE10: =IF(C10="","",P10/+(O10+P10)) -> 0.51786807 | AF10: =IF(C10="","",AE10*Q10*K10%) -> -2.3071022e+10 | AG10: =(Tabla6[[#This Row],[Fecha Vto]]-TODAY())/365 -> 0.70410959 | AJ10: =IF(C10="","",IF(G10="UVR",Q10*AI10-S10,0)) -> 0
A11: =IF(C11="","",YEAR(C11)) -> 2025 | B11: 606 | C11: 45706 | D11: Tesorería | E11: Títulos Entregados por la Nación | F11: TFIT23250746 | G11: =+_xlfn.XLOOKUP(F11,Emisiones[Mnemotécnico SEN],Emisiones[Moneda],"",0,1) -> COP | J11: =+_xlfn.XLOOKUP(F11,Emisiones[Mnemotécnico SEN],Emisiones[Fecha Vencim.],"",0,1) -> 53533 | K11: =+_xlfn.XLOOKUP(F11,Emisiones[Mnemotécnico SEN],Emisiones[Tasa de Interés],"",0,1) -> 11.5 | L11: 12.695 | M11: 97.698 | N11: =IF(C11="","",PRICE(C11,J11,K11%,L11%,100,1,3)) -> 91.144772 | O11: =IF(C11="","",M11-N11) -> 6.5532285 | P11: =IF(C11="","",100*K11%-O11) -> 4.9467715 | Q11: =IF(C11="","",IF(G11="UVR",S11/V11,S11)) -> 594000000000 | R11: =IF(C11="","",IF('Canjes desagregado'!$G11="UVR",'Canjes desagregado'!$V11*Q11*M11%,Q11*M11%)) -> 580326120000 | S11: 594000000000 | T11: =IFERROR(IF(RIGHT(F11,2)=RIGHT(YEAR(J11),2),1,0),"") -> 1 | U11: =+IF(R11="","",R11) -> 580326120000 | V11: =+IF(F11<>"",(_xlfn.XLOOKUP(C11,UVR[Fecha (dd/mm/aaaa)],UVR[Pesos colombianos por UVR],"",0,1)),"") -> 379.3837 | W11: =IF(C11="","",IF(CONCATENATE(DAY(C11),"/",MONTH(C11),"/",2000)-CONCATENATE(DAY(J11),"/",MONTH(J11),"/",2000)<0,K11%*ABS(S11),0)) -> 68310000000 | X11: =IF(S11<0,-W11,W11) -> 68310000000 | AB11: =IF(C11="","",ROUND(V11*(1+'Inflación observada '!$B$390%)^(("31-12-2025"-C11)/365),3)) -> 396.47 | AD11: =IF(C11="","",IF(G11="UVR",Q11*AB11-S11,0)) -> 0 | AE11: =IF(C11="","",P11/+(O11+P11)) -> 0.43015404 | AF11: =IF(C11="","",AE11*Q11*K11%) -> 2.9383823e+10 | AG11: =(Tabla6[[#This Row],[Fecha Vto]]-TODAY())/365 -> 20.630137 | AJ11: =IF(C11="","",IF(G11="UVR",Q11*AI11-S11,0)) -> 0
A12: =IF(C12="","",YEAR(C12)) -> 2025 | B12: 607 | C12: 45707 | D12: Tesorería | E12: Títulos Recogidos por la Nación | F12: TFIT15260826 | G12: =+_xlfn.XLOOKUP(F12,Emisiones[Mnemotécnico SEN],Emisiones[Moneda],"",0,1) -> COP | J12: =+_xlfn.XLOOKUP(F12,Emisiones[Mnemotécnico SEN],Emisiones[Fecha Vencim.],"",0,1) -> 46260 | K12: =+_xlfn.XLOOKUP(F12,Emisiones[Mnemotécnico SEN],Emisiones[Tasa de Interés],"",0,1) -> 7.5 | L12: 8.861 | M12: 101.704 | N12: =IF(C12="","",PRICE(C12,J12,K12%,L12%,100,1,3)) -> 98.066602 | O12: =IF(C12="","",M12-N12) -> 3.6373978 | P12: =IF(C12="","",100*K12%-O12) -> 3.8626022 | Q12: =IF(C12="","",IF(G12="UVR",S12/V12,S12)) -> -456000000000 | R12: =IF(C12="","",IF('Canjes desagregado'!$G12="UVR",'Canjes desagregado'!$V12*Q12*M12%,Q12*M12%)) -> -463770240000 | S12: -456000000000 | T12: =IFERROR(IF(RIGHT(F12,2)=RIGHT(YEAR(J12),2),1,0),"") -> 1 | U12: =+IF(R12="","",R12) -> -463770240000 | V12: =+IF(F12<>"",(_xlfn.XLOOKUP(C12,UVR[Fecha (dd/mm/aaaa)],UVR[Pesos colombianos por UVR],"",0,1)),"") -> 379.5105 | W12: =IF(C12="","",IF(CONCATENATE(DAY(C12),"/",MONTH(C12),"/",2000)-CONCATENATE(DAY(J12),"/",MONTH(J12),"/",2000)<0,K12%*ABS(S12),0)) -> 34200000000 | X12: =IF(S12<0,-W12,W12) -> -34200000000 | AB12: =IF(C12="","",ROUND(V12*(1+'Inflación observada '!$B$390%)^(("31-12-2025"-C12)/365),3)) -> 396.547 | AD12: =IF(C12="","",IF(G12="UVR",Q12*AB12-S12,0)) -> 0 | AE12: =IF(C12="","",P12/+(O12+P12)) -> 0.51501363 | AF12: =IF(C12="","",AE12*Q12*K12%) -> -1.7613466e+10 | AG12: =(Tabla6[[#This Row],[Fecha Vto]]-TODAY())/365 -> 0.70410959 | AJ12: =IF(C12="","",IF(G12="UVR",Q12*AI12-S12,0)) -> 0
A13: =IF(C13="","",YEAR(C13)) -> 2025 | B13: 607 | C13: 45707 | D13: Tesorería | E13: Títulos Entregados por la Nación | F13: TFIT23250746 | G13: =+_xlfn.XLOOKUP(F13,Emisiones[Mnemotécnico SEN],Emisiones[Moneda],"",0,1) -> COP | J13: =+_xlfn.XLOOKUP(F13,Emisiones[Mnemotécnico SEN],Emisiones[Fecha Vencim.],"",0,1) -> 53533 | K13: =+_xlfn.XLOOKUP(F13,Emisiones[Mnemotécnico SEN],Emisiones[Tasa de Interés],"",0,1) -> 11.5 | L13: 12.697 | M13: 97.717 | N13: =IF(C13="","",PRICE(C13,J13,K13%,L13%,100,1,3)) -> 91.131791 | O13: =IF(C13="","",M13-N13) -> 6.5852089 | P13: =IF(C13="","",100*K13%-O13) -> 4.9147911 | Q13: =IF(C13="","",IF(G13="UVR",S13/V13,S13)) -> 456000000000 | R13: =IF(C13="","",IF('Canjes desagregado'!$G13="UVR",'Canjes desagregado'!$V13*Q13*M13%,Q13*M13%)) -> 445589520000 | S13: 456000000000 | T13: =IFERROR(IF(RIGHT(F13,2)=RIGHT(YEAR(J13),2),1,0),"") -> 1 | U13: =+IF(R13="","",R13) -> 445589520000 | V13: =+IF(F13<>"",(_xlfn.XLOOKUP(C13,UVR[Fecha (dd/mm/aaaa)],UVR[Pesos colombianos por UVR],"",0,1)),"") -> 379.5105 | W13: =IF(C13="","",IF(CONCATENATE(DAY(C13),"/",MONTH(C13),"/",2000)-CONCATENATE(DAY(J13),"/",MONTH(J13),"/",2000)<0,K13%*ABS(S13),0)) -> 52440000000 | X13: =IF(S13<0,-W13,W13) -> 52440000000 | AB13: =IF(C13="","",ROUND(V13*(1+'Inflación observada '!$B$390%)^(("31-12-2025"-C13)/365),3)) -> 396.547 | AD13: =IF(C13="","",IF(G13="UVR",Q13*AB13-S13,0)) -> 0 | AE13: =IF(C13="","",P13/+(O13+P13)) -> 0.42737314 | AF13: =IF(C13="","",AE13*Q13*K13%) -> 2.2411448e+10 | AG13: =(Tabla6[[#This Row],[Fecha Vto]]-TODAY())/365 -> 20.630137 | AJ13: =IF(C13="","",IF(G13="UVR",Q13*AI13-S13,0)) -> 0
... A37: =IF(C37="","",YEAR(C37)) -> 2025 | B37: 617 | C37: 45722 | D37: Tesorería | E37: Títulos Entregados por la Nación | F37: TFIT23250746 | G37: =+_xlfn.XLOOKUP(F37,Emisiones[Mnemotécnico SEN],Emisiones[Moneda],"",0,1) -> COP | J37: =+_xlfn.XLOOKUP(F37,Emisiones[Mnemotécnico SEN],Emisiones[Fecha Vencim.],"",0,1) -> 53533 | K37: =+_xlfn.XLOOKUP(F37,Emisiones[Mnemotécnico SEN],Emisiones[Tasa de Interés],"",0,1) -> 11.5 | L37: 12.439 | M37: 99.964 | N37: =IF(C37="","",PRICE(C37,J37,K37%,L37%,100,1,3)) -> 92.905789 | O37: =IF(C37="","",M37-N37) -> 7.0582112 | P37: =IF(C37="","",100*K37%-O37) -> 4.4417888 | Q37: =IF(C37="","",IF(G37="UVR",S37/V37,S37)) -> 200000000000 | R37: =IF(C37="","",IF('Canjes desagregado'!$G37="UVR",'Canjes desagregado'!$V37*Q37*M37%,Q37*M37%)) -> 199928000000 | S37: 200000000000 | T37: =IFERROR(IF(RIGHT(F37,2)=RIGHT(YEAR(J37),2),1,0),"") -> 1 | U37: =+IF(R37="","",R37) -> 199928000000 | V37: =+IF(F37<>"",(_xlfn.XLOOKUP(C37,UVR[Fecha (dd/mm/aaaa)],UVR[Pesos colombianos por UVR],"",0,1)),"") -> 381.4175 | W37: =IF(C37="","",IF(CONCATENATE(DAY(C37),"/",MONTH(C37),"/",2000)-CONCATENATE(DAY(J37),"/",MONTH(J37),"/",2000)<0,K37%*ABS(S37),0)) -> 23000000000 | X37: =IF(S37<0,-W37,W37) -> 23000000000 | AB37: =IF(C37="","",ROUND(V37*(1+'Inflación observada '!$B$390%)^(("31-12-2025"-C37)/365),3)) -> 397.707 | AD37: =IF(C37="","",IF(G37="UVR",Q37*AB37-S37,0)) -> 0 | AE37: =IF(C37="","",P37/+(O37+P37)) -> 0.3862425 | AF37: =IF(C37="","",AE37*Q37*K37%) -> 8.8835775e+09 | AG37: =(Tabla6[[#This Row],[Fecha Vto]]-TODAY())/365 -> 20.630137 | AJ37: =IF(C37="","",IF(G37="UVR",Q37*AI37-S37,0)) -> 0
A38: =IF(C38="","",YEAR(C38)) -> 2025 | B38: 618 | C38: 45723 | D38: Tesorería | E38: Títulos Recogidos por la Nación | F38: TUVT11070525 | G38: =+_xlfn.XLOOKUP(F38,Emisiones[Mnemotécnico SEN],Emisiones[Moneda],"",0,1) -> UVR | J38: =+_xlfn.XLOOKUP(F38,Emisiones[Mnemotécnico SEN],Emisiones[Fecha Vencim.],"",0,1) -> 45784 | K38: =+_xlfn.XLOOKUP(F38,Emisiones[Mnemotécnico SEN],Emisiones[Tasa de Interés],"",0,1) -> 3.5 | L38: -0.697 | M38: 103.621 | N38: 98.569 | O38: =IF(C38="","",M38-N38) -> 5.052 | P38: =IF(C38="","",100*K38%-O38) -> -1.552 | Q38: =IF(C38="","",IF(G38="UVR",S38/V38,S38)) -> -135000000 | R38: =IF(C38="","",IF('Canjes desagregado'!$G38="UVR",'Canjes desagregado'!$V38*Q38*M38%,Q38*M38%)) -> -5.3373687e+10 | S38: -51508561500 | T38: =IFERROR(IF(RIGHT(F38,2)=RIGHT(YEAR(J38),2),1,0),"") -> 1 | U38: =+IF(R38="","",R38) -> -5.3373687e+10 | V38: =+IF(F38<>"",(_xlfn.XLOOKUP(C38,UVR[Fecha (dd/mm/aaaa)],UVR[Pesos colombianos por UVR],"",0,1)),"") -> 381.5449 | W38: =IF(C38="","",IF(CONCATENATE(DAY(C38),"/",MONTH(C38),"/",2000)-CONCATENATE(DAY(J38),"/",MONTH(J38),"/",2000)<0,K38%*ABS(S38),0)) -> 1.8027997e+09 | X38: =IF(S38<0,-W38,W38) -> -1.8027997e+09 | AB38: =IF(C38="","",ROUND(V38*(1+'Inflación observada '!$B$390%)^(("31-12-2025"-C38)/365),3)) -> 397.785 | AD38: =IF(C38="","",IF(G38="UVR",Q38*AB38-S38,0)) -> -2192413500 | AE38: =IF(C38="","",P38/+(O38+P38)) -> -0.44342857 | AF38: =IF(C38="","",AE38*Q38*K38%) -> 2095200 | AG38: =(Tabla6[[#This Row],[Fecha Vto]]-TODAY())/365 -> -0.6 | AJ38: =IF(C38="","",IF(G38="UVR",Q38*AI38-S38,0)) -> 51508561500
A39: =IF(C39="","",YEAR(C39)) -> 2025 | B39: 618 | C39: 45723 | D39: Tesorería | E39: Títulos Entregados por la Nación | F39: TUVT31190555 | G39: =+_xlfn.XLOOKUP(F39,Emisiones[Mnemotécnico SEN],Emisiones[Moneda],"",0,1) -> UVR | J39: =+_xlfn.XLOOKUP(F39,Emisiones[Mnemotécnico SEN],Emisiones[Fecha Vencim.],"",0,1) -> 56753 | K39: =+_xlfn.XLOOKUP(F39,Emisiones[Mnemotécnico SEN],Emisiones[Tasa de Interés],"",0,1) -> 5.25 | L39: 5.345 | M39: 102.77 | N39: =IF(C39="","",PRICE(C39,J39,K39%,L39%,100,1,3)) -> 98.569493 | O39: =IF(C39="","",M39-N39) -> 4.200507 | P39: =IF(C39="","",100*K39%-O39) -> 1.049493 | Q39: =IF(C39="","",IF(G39="UVR",S39/V39,S39)) -> 135000000 | R39: =IF(C39="","",IF('Canjes desagregado'!$G39="UVR",'Canjes desagregado'!$V39*Q39*M39%,Q39*M39%)) -> 5.2935349e+10 | S39: 51508561500 | T39: =IFERROR(IF(RIGHT(F39,2)=RIGHT(YEAR(J39),2),1,0),"") -> 1 | U39: =+IF(R39="","",R39) -> 5.2935349e+10 | V39: =+IF(F39<>"",(_xlfn.XLOOKUP(C39,UVR[Fecha (dd/mm/aaaa)],UVR[Pesos colombianos por UVR],"",0,1)),"") -> 381.5449 | W39: =IF(C39="","",IF(CONCATENATE(DAY(C39),"/",MONTH(C39),"/",2000)-CONCATENATE(DAY(J39),"/",MONTH(J39),"/",2000)<0,K39%*ABS(S39),0)) -> 2.7041995e+09 | X39: =IF(S39<0,-W39,W39) -> 2.7041995e+09 | AB39: =IF(C39="","",ROUND(V39*(1+'Inflación observada '!$B$390%)^(("31-12-2025"-C39)/365),3)) -> 397.785 | AD39: =IF(C39="","",IF(G39="UVR",Q39*AB39-S39,0)) -> 2192413500 | AE39: =IF(C39="","",P39/+(O39+P39)) -> 0.19990342 | AF39: =IF(C39="","",AE39*Q39*K39%) -> 1416815.5 | AG39: =(Tabla6[[#This Row],[Fecha Vto]]-TODAY())/365 -> 29.452055 | AJ39: =IF(C39="","",IF(G39="UVR",Q39*AI39-S39,0)) -> -51508561500
A40: =IF(C40="","",YEAR(C40)) -> 2025 | B40: 619 | C40: 45726 | D40: Tesorería | E40: Títulos Recogidos por la Nación | F40: TUVT11070525 | G40: =+_xlfn.XLOOKUP(F40,Emisiones[Mnemotécnico SEN],Emisiones[Moneda],"",0,1) -> UVR | J40: =+_xlfn.XLOOKUP(F40,Emisiones[Mnemotécnico SEN],Emisiones[Fecha Vencim.],"",0,1) -> 45784 | K40: =+_xlfn.XLOOKUP(F40,Emisiones[Mnemotécnico SEN],Emisiones[Tasa de Interés],"",0,1) -> 3.5 | L40: -1.032 | M40: 103.671 | N40: 101.727 | O40: =IF(C40="","",M40-N40) -> 1.944 | P40: =IF(C40="","",100*K40%-O40) -> 1.556 | Q40: =IF(C40="","",IF(G40="UVR",S40/V40,S40)) -> -205000000 | R40: =IF(C40="","",IF('Canjes desagregado'!$G40="UVR",'Canjes desagregado'!$V40*Q40*M40%,Q40*M40%)) -> -8.1169373e+10 | S40: -78295158000 | T40: =IFERROR(IF(RIGHT(F40,2)=RIGHT(YEAR(J40),2),1,0),"") -> 1 | U40: =+IF(R40="","",R40) -> -8.1169373e+10 | V40: =+IF(F40<>"",(_xlfn.XLOOKUP(C40,UVR[Fecha (dd/mm/aaaa)],UVR[Pesos colombianos por UVR],"",0,1)),"") -> 381.9276 | W40: =IF(C40="","",IF(CONCATENATE(DAY(C40),"/",MONTH(C40),"/",2000)-CONCATENATE(DAY(J40),"/",MONTH(J40),"/",2000)<0,K40%*ABS(S40),0)) -> 2.7403305e+09 | X40: =IF(S40<0,-W40,W40) -> -2.7403305e+09 | AB40: =IF(C40="","",ROUND(V40*(1+'Inflación observada '!$B$391%)^(("31-12-2025"-C40)/365),3)) -> 398.201 | AD40: =IF(C40="","",IF(G40="UVR",Q40*AB40-S40,0)) -> -3336047000 | AE40: =IF(C40="","",P40/+(O40+P40)) -> 0.44457143 | AF40: =IF(C40="","",AE40*Q40*K40%) -> -3189800 | AG40: =(Tabla6[[#This Row],[Fecha Vto]]-TODAY())/365 -> -0.6 | AJ40: =IF(C40="","",IF(G40="UVR",Q40*AI40-S40,0)) -> 78295158000
A41: =IF(C41="","",YEAR(C41)) -> 2025 | B41: 619 | C41: 45726 | D41: Tesorería | E41: Títulos Entregados por la Nación | F41: TUVT31190555 | G41: =+_xlfn.XLOOKUP(F41,Emisiones[Mnemotécnico SEN],Emisiones[Moneda],"",0,1) -> UVR | J41: =+_xlfn.XLOOKUP(F41,Emisiones[Mnemotécnico SEN],Emisiones[Fecha Vencim.],"",0,1) -> 56753 | K41: =+_xlfn.XLOOKUP(F41,Emisiones[Mnemotécnico SEN],Emisiones[Tasa de Interés],"",0,1) -> 5.25 | L41: 5.385 | M41: 102.229 | N41: =IF(C41="","",PRICE(C41,J41,K41%,L41%,100,1,3)) -> 97.986117 | O41: =IF(C41="","",M41-N41) -> 4.2428831 | P41: =IF(C41="","",100*K41%-O41) -> 1.0071169 | Q41: =IF(C41="","",IF(G41="UVR",S41/V41,S41)) -> 205000000 | R41: =IF(C41="","",IF('Canjes desagregado'!$G41="UVR",'Canjes desagregado'!$V41*Q41*M41%,Q41*M41%)) -> 8.0040357e+10 | S41: 78295158000 | T41: =IFERROR(IF(RIGHT(F41,2)=RIGHT(YEAR(J41),2),1,0),"") -> 1 | U41: =+IF(R41="","",R41) -> 8.0040357e+10 | V41: =+IF(F41<>"",(_xlfn.XLOOKUP(C41,UVR[Fecha (dd/mm/aaaa)],UVR[Pesos colombianos por UVR],"",0,1)),"") -> 381.9276 | W41: =IF(C41="","",IF(CONCATENATE(DAY(C41),"/",MONTH(C41),"/",2000)-CONCATENATE(DAY(J41),"/",MONTH(J41),"/",2000)<0,K41%*ABS(S41),0)) -> 4110495795 | X41: =IF(S41<0,-W41,W41) -> 4110495795 | AB41: =IF(C41="","",ROUND(V41*(1+'Inflación observada '!$B$391%)^(("31-12-2025"-C41)/365),3)) -> 398.201 | AD41: =IF(C41="","",IF(G41="UVR",Q41*AB41-S41,0)) -> 3336047000 | AE41: =IF(C41="","",P41/+(O41+P41)) -> 0.19183179 | AF41: =IF(C41="","",AE41*Q41*K41%) -> 2064589.7 | AG41: =(Tabla6[[#This Row],[Fecha Vto]]-TODAY())/365 -> 29.452055 | AJ41: =IF(C41="","",IF(G41="UVR",Q41*AI41-S41,0)) -> -78295158000
A42: =IF(C42="","",YEAR(C42)) -> 2025 | B42: 620 | C42: 45727 | D42: Tesorería | E42: Títulos Recogidos por la Nación | F42: TUVT11070525 | G42: =+_xlfn.XLOOKUP(F42,Emisiones[Mnemotécnico SEN],Emisiones[Moneda],"",0,1) -> UVR | J42: =+_xlfn.XLOOKUP(F42,Emisiones[Mnemotécnico SEN],Emisiones[Fecha Vencim.],"",0,1) -> 45784 | K42: =+_xlfn.XLOOKUP(F42,Emisiones[Mnemotécnico SEN],Emisiones[Tasa de Interés],"",0,1) -> 3.5 | L42: -1.188 | M42: 103.693 | N42: 100.74 | O42: =IF(C42="","",M42-N42) -> 2.953 | P42: =IF(C42="","",100*K42%-O42) -> 0.547 | Q42: =IF(C42="","",IF(G42="UVR",S42/V42,S42)) -> -465000000 | R42: =IF(C42="","",IF('Canjes desagregado'!$G42="UVR",'Canjes desagregado'!$V42*Q42*M42%,Q42*M42%)) -> -1.8421649e+11 | S42: -177655668000 | T42: =IFERROR(IF(RIGHT(F42,2)=RIGHT(YEAR(J42),2),1,0),"") -> 1 | U42: =+IF(R42="","",R42) -> -1.8421649e+11 | V42: =+IF(F42<>"",(_xlfn.XLOOKUP(C42,UVR[Fecha (dd/mm/aaaa)],UVR[Pesos colombianos por UVR],"",0,1)),"") -> 382.0552 | W42: =IF(C42="","",IF(CONCATENATE(DAY(C42),"/",MONTH(C42),"/",2000)-CONCATENATE(DAY(J42),"/",MONTH(J42),"/",2000)<0,K42%*ABS(S42),0)) -> 6.2179484e+09 | X42: =IF(S42<0,-W42,W42) -> -6.2179484e+09 | AB42: =IF(C42="","",ROUND(V42*(1+'Inflación observada '!$B$391%)^(("31-12-2025"-C42)/365),3)) -> 398.278 | AD42: =IF(C42="","",IF(G42="UVR",Q42*AB42-S42,0)) -> -7543602000 | AE42: =IF(C42="","",P42/+(O42+P42)) -> 0.15628571 | AF42: =IF(C42="","",AE42*Q42*K42%) -> -2543550 | AG42: =(Tabla6[[#This Row],[Fecha Vto]]-TODAY())/365 -> -0.6 | AJ42: =IF(C42="","",IF(G42="UVR",Q42*AI42-S42,0)) -> 177655668000
A43: =IF(C43="","",YEAR(C43)) -> 2025 | B43: 620 | C43: 45727 | D43: Tesorería | E43: Títulos Entregados por la Nación | F43: TUVT31190555 | G43: =+_xlfn.XLOOKUP(F43,Emisiones[Mnemotécnico SEN],Emisiones[Moneda],"",0,1) -> UVR | J43: =+_xlfn.XLOOKUP(F43,Emisiones[Mnemotécnico SEN],Emisiones[Fecha Vencim.],"",0,1) -> 56753 | K43: =+_xlfn.XLOOKUP(F43,Emisiones[Mnemotécnico SEN],Emisiones[Tasa de Interés],"",0,1) -> 5.25 | L43: 5.39 | M43: 102.171 | N43: =IF(C43="","",PRICE(C43,J43,K43%,L43%,100,1,3)) -> 97.913768 | O43: =IF(C43="","",M43-N43) -> 4.257232 | P43: =IF(C43="","",100*K43%-O43) -> 0.992768 | Q43: =IF(C43="","",IF(G43="UVR",S43/V43,S43)) -> 465000000 | R43: =IF(C43="","",IF('Canjes desagregado'!$G43="UVR",'Canjes desagregado'!$V43*Q43*M43%,Q43*M43%)) -> 1.8151257e+11 | S43: 177655668000 | T43: =IFERROR(IF(RIGHT(F43,2)=RIGHT(YEAR(J43),2),1,0),"") -> 1 | U43: =+IF(R43="","",R43) -> 1.8151257e+11 | V43: =+IF(F43<>"",(_xlfn.XLOOKUP(C43,UVR[Fecha (dd/mm/aaaa)],UVR[Pesos colombianos por UVR],"",0,1)),"") -> 382.0552 | W43: =IF(C43="","",IF(CONCATENATE(DAY(C43),"/",MONTH(C43),"/",2000)-CONCATENATE(DAY(J43),"/",MONTH(J43),"/",2000)<0,K43%*ABS(S43),0)) -> 9326922570 | X43: =IF(S43<0,-W43,W43) -> 9326922570 | AB43: =IF(C43="","",ROUND(V43*(1+'Inflación observada '!$B$391%)^(("31-12-2025"-C43)/365),3)) -> 398.278 | AD43: =IF(C43="","",IF(G43="UVR",Q43*AB43-S43,0)) -> 7543602000 | AE43: =IF(C43="","",P43/+(O43+P43)) -> 0.18909867 | AF43: =IF(C43="","",AE43*Q43*K43%) -> 4616371.2 | AG43: =(Tabla6[[#This Row],[Fecha Vto]]-TODAY())/365 -> 29.452055 | AJ43: =IF(C43="","",IF(G43="UVR",Q43*AI43-S43,0)) -> -177655668000
A44: =IF(C44="","",YEAR(C44)) -> 2025 | B44: 621 | C44: 45728 | D44: Tesorería | E44: Títulos Recogidos por la Nación | F44: TFIT08261125 | G44: =+_xlfn.XLOOKUP(F44,Emisiones[Mnemotécnico SEN],Emisiones[Moneda],"",0,1) -> COP | J44: =+_xlfn.XLOOKUP(F44,Emisiones[Mnemotécnico SEN],Emisiones[Fecha Vencim.],"",0,1) -> 45987 | K44: =+_xlfn.XLOOKUP(F44,Emisiones[Mnemotécnico SEN],Emisiones[Tasa de Interés],"",0,1) -> 6.25 | L44: 8.906 | M44: 100.009 | N44: =IF(C44="","",PRICE(C44,J44,K44%,L44%,100,1,3)) -> 98.119469 | O44: =IF(C44="","",M44-N44) -> 1.8895315 | P44: =IF(C44="","",100*K44%-O44) -> 4.3604685 | Q44: =IF(C44="","",IF(G44="UVR",S44/V44,S44)) -> -90000000000 | R44: =IF(C44="","",IF('Canjes desagregado'!$G44="UVR",'Canjes desagregado'!$V44*Q44*M44%,Q44*M44%)) -> -90008100000 | S44: -90000000000 | T44: =IFERROR(IF(RIGHT(F44,2)=RIGHT(YEAR(J44),2),1,0),"") -> 1 | U44: =+IF(R44="","",R44) -> -90008100000 | V44: =+IF(F44<>"",(_xlfn.XLOOKUP(C44,UVR[Fecha (dd/mm/aaaa)],UVR[Pesos colombianos por UVR],"",0,1)),"") -> 382.1829 | W44: =IF(C44="","",IF(CONCATENATE(DAY(C44),"/",MONTH(C44),"/",2000)-CONCATENATE(DAY(J44),"/",MONTH(J44),"/",2000)<0,K44%*ABS(S44),0)) -> 5625000000 | X44: =IF(S44<0,-W44,W44) -> -5625000000 | AB44: =IF(C44="","",ROUND(V44*(1+'Inflación observada '!$B$391%)^(("31-12-2025"-C44)/365),3)) -> 398.355 | AD44: =IF(C44="","",IF(G44="UVR",Q44*AB44-S44,0)) -> 0 | AE44: =IF(C44="","",P44/+(O44+P44)) -> 0.69767496 | AF44: =IF(C44="","",AE44*Q44*K44%) -> -3.9244217e+09 | AG44: =(Tabla6[[#This Row],[Fecha Vto]]-TODAY())/365 -> -0.043835616 | AJ44: =IF(C44="","",IF(G44="UVR",Q44*AI44-S44,0)) -> 0
A45: =IF(C45="","",YEAR(C45)) -> 2025 | B45: 621 | C45: 45728 | D45: Tesorería | E45: Títulos Recogidos por la Nación | F45: TFIT15260826 | G45: =+_xlfn.XLOOKUP(F45,Emisiones[Mnemotécnico SEN],Emisiones[Moneda],"",0,1) -> COP | J45: =+_xlfn.XLOOKUP(F45,Emisiones[Mnemotécnico SEN],Emisiones[Fecha Vencim.],"",0,1) -> 46260 | K45: =+_xlfn.XLOOKUP(F45,Emisiones[Mnemotécnico SEN],Emisiones[Tasa de Interés],"",0,1) -> 7.5 | L45: 8.889 | M45: 102.165 | N45: =IF(C45="","",PRICE(C45,J45,K45%,L45%,100,1,3)) -> 98.09666 | O45: =IF(C45="","",M45-N45) -> 4.0683398 | P45: =IF(C45="","",100*K45%-O45) -> 3.4316602 | Q45: =IF(C45="","",IF(G45="UVR",S45/V45,S45)) -> -60000000000 | R45: =IF(C45="","",IF('Canjes desagregado'!$G45="UVR",'Canjes desagregado'!$V45*Q45*M45%,Q45*M45%)) -> -6.1299e+10 | S45: -60000000000 | T45: =IFERROR(IF(RIGHT(F45,2)=RIGHT(YEAR(J45),2),1,0),"") -> 1 | U45: =+IF(R45="","",R45) -> -6.1299e+10 | V45: =+IF(F45<>"",(_xlfn.XLOOKUP(C45,UVR[Fecha (dd/mm/aaaa)],UVR[Pesos colombianos por UVR],"",0,1)),"") -> 382.1829 | W45: =IF(C45="","",IF(CONCATENATE(DAY(C45),"/",MONTH(C45),"/",2000)-CONCATENATE(DAY(J45),"/",MONTH(J45),"/",2000)<0,K45%*ABS(S45),0)) -> 4500000000 | X45: =IF(S45<0,-W45,W45) -> -4500000000 | AB45: =IF(C45="","",ROUND(V45*(1+'Inflación observada '!$B$391%)^(("31-12-2025"-C45)/365),3)) -> 398.355 | AD45: =IF(C45="","",IF(G45="UVR",Q45*AB45-S45,0)) -> 0 | AE45: =IF(C45="","",P45/+(O45+P45)) -> 0.45755469 | AF45: =IF(C45="","",AE45*Q45*K45%) -> -2.0589961e+09 | AG45: =(Tabla6[[#This Row],[Fecha Vto]]-TODAY())/365 -> 0.70410959 | AJ45: =IF(C45="","",IF(G45="UVR",Q45*AI45-S45,0)) -> 0
A46: =IF(C46="","",YEAR(C46)) -> 2025 | B46: 621 | C46: 45728 | D46: Tesorería | E46: Títulos Entregados por la Nación | F46: TFIT23250746 | G46: =+_xlfn.XLOOKUP(F46,Emisiones[Mnemotécnico SEN],Emisiones[Moneda],"",0,1) -> COP | J46: =+_xlfn.XLOOKUP(F46,Emisiones[Mnemotécnico SEN],Emisiones[Fecha Vencim.],"",0,1) -> 53533 | K46: =+_xlfn.XLOOKUP(F46,Emisiones[Mnemotécnico SEN],Emisiones[Tasa de Interés],"",0,1) -> 11.5 | L46: 12.49 | M46: 99.803 | N46: =IF(C46="","",PRICE(C46,J46,K46%,L46%,100,1,3)) -> 92.55605 | O46: =IF(C46="","",M46-N46) -> 7.2469499 | P46: =IF(C46="","",100*K46%-O46) -> 4.2530501 | Q46: =IF(C46="","",IF(G46="UVR",S46/V46,S46)) -> 150000000000 | R46: =IF(C46="","",IF('Canjes desagregado'!$G46="UVR",'Canjes desagregado'!$V46*Q46*M46%,Q46*M46%)) -> 149704500000 | S46: 150000000000 | T46: =IFERROR(IF(RIGHT(F46,2)=RIGHT(YEAR(J46),2),1,0),"") -> 1 | U46: =+IF(R46="","",R46) -> 149704500000 | V46: =+IF(F46<>"",(_xlfn.XLOOKUP(C46,UVR[Fecha (dd/mm/aaaa)],UVR[Pesos colombianos por UVR],"",0,1)),"") -> 382.1829 | W46: =IF(C46="","",IF(CONCATENATE(DAY(C46),"/",MONTH(C46),"/",2000)-CONCATENATE(DAY(J46),"/",MONTH(J46),"/",2000)<0,K46%*ABS(S46),0)) -> 17250000000 | X46: =IF(S46<0,-W46,W46) -> 17250000000 | AB46: =IF(C46="","",ROUND(V46*(1+'Inflación observada '!$B$391%)^(("31-12-2025"-C46)/365),3)) -> 398.355 | AD46: =IF(C46="","",IF(G46="UVR",Q46*AB46-S46,0)) -> 0 | AE46: =IF(C46="","",P46/+(O46+P46)) -> 0.36983044 | AF46: =IF(C46="","",AE46*Q46*K46%) -> 6.3795752e+09 | AG46: =(Tabla6[[#This Row],[Fecha Vto]]-TODAY())/365 -> 20.630137 | AJ46: =IF(C46="","",IF(G46="UVR",Q46*AI46-S46,0)) -> 0
A47: =IF(C47="","",YEAR(C47)) -> 2025 | B47: 622 | C47: 45729 | D47: Tesorería | E47: Títulos Recogidos por la Nación | F47: TFIT08261125 | G47: =+_xlfn.XLOOKUP(F47,Emisiones[Mnemotécnico SEN],Emisiones[Moneda],"",0,1) -> COP | J47: =+_xlfn.XLOOKUP(F47,Emisiones[Mnemotécnico SEN],Emisiones[Fecha Vencim.],"",0,1) -> 45987 | K47: =+_xlfn.XLOOKUP(F47,Emisiones[Mnemotécnico SEN],Emisiones[Tasa de Interés],"",0,1) -> 6.25 | L47: 8.905 | M47: 100.033 | N47: =IF(C47="","",PRICE(C47,J47,K47%,L47%,100,1,3)) -> 98.12595 | O47: =IF(C47="","",M47-N47) -> 1.9070502 | P47: =IF(C47="","",100*K47%-O47) -> 4.3429498 | Q47: =IF(C47="","",IF(G47="UVR",S47/V47,S47)) -> -91000000000 | R47: =IF(C47="","",IF('Canjes desagregado'!$G47="UVR",'Canjes desagregado'!$V47*Q47*M47%,Q47*M47%)) -> -91030030000 | S47: -91000000000 | T47: =IFERROR(IF(RIGHT(F47,2)=RIGHT(YEAR(J47),2),1,0),"") -> 1 | U47: =+IF(R47="","",R47) -> -91030030000 | V47: =+IF(F47<>"",(_xlfn.XLOOKUP(C47,UVR[Fecha (dd/mm/aaaa)],UVR[Pesos colombianos por UVR],"",0,1)),"") -> 382.3107 | W47: =IF(C47="","",IF(CONCATENATE(DAY(C47),"/",MONTH(C47),"/",2000)-CONCATENATE(DAY(J47),"/",MONTH(J47),"/",2000)<0,K47%*ABS(S47),0)) -> 5687500000 | X47: =IF(S47<0,-W47,W47) -> -5687500000 | AB47: =IF(C47="","",ROUND(V47*(1+'Inflación observada '!$B$391%)^(("31-12-2025"-C47)/365),3)) -> 398.432 | AD47: =IF(C47="","",IF(G47="UVR",Q47*AB47-S47,0)) -> 0 | AE47: =IF(C47="","",P47/+(O47+P47)) -> 0.69487197 | AF47: =IF(C47="","",AE47*Q47*K47%) -> -3.9520844e+09 | AG47: =(Tabla6[[#This Row],[Fecha Vto]]-TODAY())/365 -> -0.043835616 | AJ47: =IF(C47="","",IF(G47="UVR",Q47*AI47-S47,0)) -> 0
A48: =IF(C48="","",YEAR(C48)) -> 2025 | B48: 622 | C48: 45729 | D48: Tesorería | E48: Títulos Recogidos por la Nación | F48: TFIT15260826 | G48: =+_xlfn.XLOOKUP(F48,Emisiones[Mnemotécnico SEN],Emisiones[Moneda],"",0,1) -> COP | J48: =+_xlfn.XLOOKUP(F48,Emisiones[Mnemotécnico SEN],Emisiones[Fecha Vencim.],"",0,1) -> 46260 | K48: =+_xlfn.XLOOKUP(F48,Emisiones[Mnemotécnico SEN],Emisiones[Tasa de Interés],"",0,1) -> 7.5 | L48: 8.858 | M48: 102.229 | N48: =IF(C48="","",PRICE(C48,J48,K48%,L48%,100,1,3)) -> 98.140235 | O48: =IF(C48="","",M48-N48) -> 4.0887651 | P48: =IF(C48="","",100*K48%-O48) -> 3.4112349 | Q48: =IF(C48="","",IF(G48="UVR",S48/V48,S48)) -> -90000000000 | R48: =IF(C48="","",IF('Canjes desagregado'!$G48="UVR",'Canjes desagregado'!$V48*Q48*M48%,Q48*M48%)) -> -92006100000 | S48: -90000000000 | T48: =IFERROR(IF(RIGHT(F48,2)=RIGHT(YEAR(J48),2),1,0),"") -> 1 | U48: =+IF(R48="","",R48) -> -92006100000 | V48: =+IF(F48<>"",(_xlfn.XLOOKUP(C48,UVR[Fecha (dd/mm/aaaa)],UVR[Pesos colombianos por UVR],"",0,1)),"") -> 382.3107 | W48: =IF(C48="","",IF(CONCATENATE(DAY(C48),"/",MONTH(C48),"/",2000)-CONCATENATE(DAY(J48),"/",MONTH(J48),"/",2000)<0,K48%*ABS(S48),0)) -> 6750000000 | X48: =IF(S48<0,-W48,W48) -> -6750000000 | AB48: =IF(C48="","",ROUND(V48*(1+'Inflación observada '!$B$391%)^(("31-12-2025"-C48)/365),3)) -> 398.432 | AD48: =IF(C48="","",IF(G48="UVR",Q48*AB48-S48,0)) -> 0 | AE48: =IF(C48="","",P48/+(O48+P48)) -> 0.45483132 | AF48: =IF(C48="","",AE48*Q48*K48%) -> -3.0701114e+09 | AG48: =(Tabla6[[#This Row],[Fecha Vto]]-TODAY())/365 -> 0.70410959 | AJ48: =IF(C48="","",IF(G48="UVR",Q48*AI48-S48,0)) -> 0
A49: =IF(C49="","",YEAR(C49)) -> 2025 | B49: 622 | C49: 45729 | D49: Tesorería | E49: Títulos Entregados por la Nación | F49: TFIT23250746 | G49: =+_xlfn.XLOOKUP(F49,Emisiones[Mnemotécnico SEN],Emisiones[Moneda],"",0,1) -> COP | J49: =+_xlfn.XLOOKUP(F49,Emisiones[Mnemotécnico SEN],Emisiones[Fecha Vencim.],"",0,1) -> 53533 | K49: =+_xlfn.XLOOKUP(F49,Emisiones[Mnemotécnico SEN],Emisiones[Tasa de Interés],"",0,1) -> 11.5 | L49: 12.496 | M49: 99.794 | N49: =IF(C49="","",PRICE(C49,J49,K49%,L49%,100,1,3)) -> 92.51529 | O49: =IF(C49="","",M49-N49) -> 7.2787103 | P49: =IF(C49="","",100*K49%-O49) -> 4.2212897 | Q49: =IF(C49="","",IF(G49="UVR",S49/V49,S49)) -> 181000000000 | R49: =IF(C49="","",IF('Canjes desagregado'!$G49="UVR",'Canjes desagregado'!$V49*Q49*M49%,Q49*M49%)) -> 180627140000 | S49: 181000000000 | T49: =IFERROR(IF(RIGHT(F49,2)=RIGHT(YEAR(J49),2),1,0),"") -> 1 | U49: =+IF(R49="","",R49) -> 180627140000 | V49: =+IF(F49<>"",(_xlfn.XLOOKUP(C49,UVR[Fecha (dd/mm/aaaa)],UVR[Pesos colombianos por UVR],"",0,1)),"") -> 382.3107 | W49: =IF(C49="","",IF(CONCATENATE(DAY(C49),"/",MONTH(C49),"/",2000)-CONCATENATE(DAY(J49),"/",MONTH(J49),"/",2000)<0,K49%*ABS(S49),0)) -> 20815000000 | X49: =IF(S49<0,-W49,W49) -> 20815000000 | AB49: =IF(C49="","",ROUND(V49*(1+'Inflación observada '!$B$391%)^(("31-12-2025"-C49)/365),3)) -> 398.432 | AD49: =IF(C49="","",IF(G49="UVR",Q49*AB49-S49,0)) -> 0 | AE49: =IF(C49="","",P49/+(O49+P49)) -> 0.36706867 | AF49: =IF(C49="","",AE49*Q49*K49%) -> 7.6405344e+09 | AG49: =(Tabla6[[#This Row],[Fecha Vto]]-TODAY())/365 -> 20.630137 | AJ49: =IF(C49="","",IF(G49="UVR",Q49*AI49-S49,0)) -> 0
